ERROR:__main__:2022-12-25 19:18:56,379:MaxAttempt(3) exhausted. User0
Traceback (most recent call last):
  File "D:\Synced folder 2\tradex_opinionTrading\codes_2\venv\lib\site-packages\urllib3\connection.py", line 174, in _new_conn
    conn = connection.create_connection(
  File "D:\Synced folder 2\tradex_opinionTrading\codes_2\venv\lib\site-packages\urllib3\util\connection.py", line 72, in create_connection
    for res in socket.getaddrinfo(host, port, family, socket.SOCK_STREAM):
  File "C:\Users\aniru\AppData\Local\Programs\Python\Python310\lib\socket.py", line 955, in getaddrinfo
    for res in _socket.getaddrinfo(host, port, family, type, proto, flags):
socket.gaierror: [Errno 11001] getaddrinfo failed

During handling of the above exception, another exception occurred:

Traceback (most recent call last):
  File "D:\Synced folder 2\tradex_opinionTrading\codes_2\venv\lib\site-packages\urllib3\connectionpool.py", line 703, in urlopen
    httplib_response = self._make_request(
  File "D:\Synced folder 2\tradex_opinionTrading\codes_2\venv\lib\site-packages\urllib3\connectionpool.py", line 386, in _make_request
    self._validate_conn(conn)
  File "D:\Synced folder 2\tradex_opinionTrading\codes_2\venv\lib\site-packages\urllib3\connectionpool.py", line 1042, in _validate_conn
    conn.connect()
  File "D:\Synced folder 2\tradex_opinionTrading\codes_2\venv\lib\site-packages\urllib3\connection.py", line 358, in connect
    self.sock = conn = self._new_conn()
  File "D:\Synced folder 2\tradex_opinionTrading\codes_2\venv\lib\site-packages\urllib3\connection.py", line 186, in _new_conn
    raise NewConnectionError(
urllib3.exceptions.NewConnectionError: <urllib3.connection.HTTPSConnection object at 0x000001D19C864910>: Failed to establish a new connection: [Errno 11001] getaddrinfo failed

During handling of the above exception, another exception occurred:

Traceback (most recent call last):
  File "D:\Synced folder 2\tradex_opinionTrading\codes_2\venv\lib\site-packages\requests\adapters.py", line 489, in send
    resp = conn.urlopen(
  File "D:\Synced folder 2\tradex_opinionTrading\codes_2\venv\lib\site-packages\urllib3\connectionpool.py", line 787, in urlopen
    retries = retries.increment(
  File "D:\Synced folder 2\tradex_opinionTrading\codes_2\venv\lib\site-packages\urllib3\util\retry.py", line 592, in increment
    raise MaxRetryError(_pool, url, error or ResponseError(cause))
urllib3.exceptions.MaxRetryError: HTTPSConnectionPool(host='api.theox.co', port=443): Max retries exceeded with url: /v2/transactions (Caused by NewConnectionError('<urllib3.connection.HTTPSConnection object at 0x000001D19C864910>: Failed to establish a new connection: [Errno 11001] getaddrinfo failed'))

During handling of the above exception, another exception occurred:

Traceback (most recent call last):
  File "D:\Synced folder 2\tradex_opinionTrading\codes_2\api_caller.py", line 118, in tradex_caller
    response = req.post(url, data=body, headers=headers).json()
  File "D:\Synced folder 2\tradex_opinionTrading\codes_2\venv\lib\site-packages\requests\api.py", line 115, in post
    return request("post", url, data=data, json=json, **kwargs)
  File "D:\Synced folder 2\tradex_opinionTrading\codes_2\venv\lib\site-packages\requests\api.py", line 59, in request
    return session.request(method=method, url=url, **kwargs)
  File "D:\Synced folder 2\tradex_opinionTrading\codes_2\venv\lib\site-packages\requests\sessions.py", line 587, in request
    resp = self.send(prep, **send_kwargs)
  File "D:\Synced folder 2\tradex_opinionTrading\codes_2\venv\lib\site-packages\requests\sessions.py", line 701, in send
    r = adapter.send(request, **kwargs)
  File "D:\Synced folder 2\tradex_opinionTrading\codes_2\venv\lib\site-packages\requests\adapters.py", line 565, in send
    raise ConnectionError(e, request=request)
requests.exceptions.ConnectionError: HTTPSConnectionPool(host='api.theox.co', port=443): Max retries exceeded with url: /v2/transactions (Caused by NewConnectionError('<urllib3.connection.HTTPSConnection object at 0x000001D19C864910>: Failed to establish a new connection: [Errno 11001] getaddrinfo failed'))

During handling of the above exception, another exception occurred:

Traceback (most recent call last):
  File "D:\Synced folder 2\tradex_opinionTrading\codes_2\main_strategy_run.py", line 128, in <module>
    strat_obj_dict[j].update()
  File "D:\Synced folder 2\tradex_opinionTrading\codes_2\strat7.py", line 723, in update
    self._set_qty()
  File "D:\Synced folder 2\tradex_opinionTrading\codes_2\strat7.py", line 390, in _set_qty
    self.my_avgbuy_price_yes, self.my_avgsell_price_yes, self.my_avgbuy_price_no, self.my_avgsell_price_no, self.falseavgbuyyes, self.falseavgbuyno = self.trans.get_avg_buysell_price(
  File "D:\Synced folder 2\tradex_opinionTrading\codes_2\transactions.py", line 125, in get_avg_buysell_price
    df = self.get_event_transactions(event_id)
  File "D:\Synced folder 2\tradex_opinionTrading\codes_2\transactions.py", line 118, in get_event_transactions
    df = self.clean_transactions_df()
  File "D:\Synced folder 2\tradex_opinionTrading\codes_2\transactions.py", line 102, in clean_transactions_df
    df = self._get_transactions_df()
  File "D:\Synced folder 2\tradex_opinionTrading\codes_2\transactions.py", line 24, in _get_transactions_df
    resp1 = pd.DataFrame(self.api_obj.tradex_caller("transactions"))
  File "D:\Synced folder 2\tradex_opinionTrading\codes_2\api_caller.py", line 140, in tradex_caller
    raise Exception(f"MaxAttempt({retry_attempts}) exhausted. User{self.userid}")
Exception: MaxAttempt(3) exhausted. User0
ERROR:__main__:2022-12-25 19:19:38,065:MaxAttempt(3) exhausted. User0
Traceback (most recent call last):
  File "D:\Synced folder 2\tradex_opinionTrading\codes_2\venv\lib\site-packages\urllib3\connection.py", line 174, in _new_conn
    conn = connection.create_connection(
  File "D:\Synced folder 2\tradex_opinionTrading\codes_2\venv\lib\site-packages\urllib3\util\connection.py", line 72, in create_connection
    for res in socket.getaddrinfo(host, port, family, socket.SOCK_STREAM):
  File "C:\Users\aniru\AppData\Local\Programs\Python\Python310\lib\socket.py", line 955, in getaddrinfo
    for res in _socket.getaddrinfo(host, port, family, type, proto, flags):
socket.gaierror: [Errno 11001] getaddrinfo failed

During handling of the above exception, another exception occurred:

Traceback (most recent call last):
  File "D:\Synced folder 2\tradex_opinionTrading\codes_2\venv\lib\site-packages\urllib3\connectionpool.py", line 703, in urlopen
    httplib_response = self._make_request(
  File "D:\Synced folder 2\tradex_opinionTrading\codes_2\venv\lib\site-packages\urllib3\connectionpool.py", line 386, in _make_request
    self._validate_conn(conn)
  File "D:\Synced folder 2\tradex_opinionTrading\codes_2\venv\lib\site-packages\urllib3\connectionpool.py", line 1042, in _validate_conn
    conn.connect()
  File "D:\Synced folder 2\tradex_opinionTrading\codes_2\venv\lib\site-packages\urllib3\connection.py", line 358, in connect
    self.sock = conn = self._new_conn()
  File "D:\Synced folder 2\tradex_opinionTrading\codes_2\venv\lib\site-packages\urllib3\connection.py", line 186, in _new_conn
    raise NewConnectionError(
urllib3.exceptions.NewConnectionError: <urllib3.connection.HTTPSConnection object at 0x000001D19C922890>: Failed to establish a new connection: [Errno 11001] getaddrinfo failed

During handling of the above exception, another exception occurred:

Traceback (most recent call last):
  File "D:\Synced folder 2\tradex_opinionTrading\codes_2\venv\lib\site-packages\requests\adapters.py", line 489, in send
    resp = conn.urlopen(
  File "D:\Synced folder 2\tradex_opinionTrading\codes_2\venv\lib\site-packages\urllib3\connectionpool.py", line 787, in urlopen
    retries = retries.increment(
  File "D:\Synced folder 2\tradex_opinionTrading\codes_2\venv\lib\site-packages\urllib3\util\retry.py", line 592, in increment
    raise MaxRetryError(_pool, url, error or ResponseError(cause))
urllib3.exceptions.MaxRetryError: HTTPSConnectionPool(host='api.theox.co', port=443): Max retries exceeded with url: /v2/lastTradesInfo (Caused by NewConnectionError('<urllib3.connection.HTTPSConnection object at 0x000001D19C922890>: Failed to establish a new connection: [Errno 11001] getaddrinfo failed'))

During handling of the above exception, another exception occurred:

Traceback (most recent call last):
  File "D:\Synced folder 2\tradex_opinionTrading\codes_2\api_caller.py", line 118, in tradex_caller
    response = req.post(url, data=body, headers=headers).json()
  File "D:\Synced folder 2\tradex_opinionTrading\codes_2\venv\lib\site-packages\requests\api.py", line 115, in post
    return request("post", url, data=data, json=json, **kwargs)
  File "D:\Synced folder 2\tradex_opinionTrading\codes_2\venv\lib\site-packages\requests\api.py", line 59, in request
    return session.request(method=method, url=url, **kwargs)
  File "D:\Synced folder 2\tradex_opinionTrading\codes_2\venv\lib\site-packages\requests\sessions.py", line 587, in request
    resp = self.send(prep, **send_kwargs)
  File "D:\Synced folder 2\tradex_opinionTrading\codes_2\venv\lib\site-packages\requests\sessions.py", line 701, in send
    r = adapter.send(request, **kwargs)
  File "D:\Synced folder 2\tradex_opinionTrading\codes_2\venv\lib\site-packages\requests\adapters.py", line 565, in send
    raise ConnectionError(e, request=request)
requests.exceptions.ConnectionError: HTTPSConnectionPool(host='api.theox.co', port=443): Max retries exceeded with url: /v2/lastTradesInfo (Caused by NewConnectionError('<urllib3.connection.HTTPSConnection object at 0x000001D19C922890>: Failed to establish a new connection: [Errno 11001] getaddrinfo failed'))

During handling of the above exception, another exception occurred:

Traceback (most recent call last):
  File "D:\Synced folder 2\tradex_opinionTrading\codes_2\main_strategy_run.py", line 128, in <module>
    strat_obj_dict[j].update()
  File "D:\Synced folder 2\tradex_opinionTrading\codes_2\strat7.py", line 714, in update
    self.priceatri.update_priceatri()
  File "D:\Synced folder 2\tradex_opinionTrading\codes_2\price_attributes.py", line 117, in update_priceatri
    self.update_event()
  File "D:\Synced folder 2\tradex_opinionTrading\codes_2\event_params.py", line 31, in update_event
    self.last_executed_trades = self.lti.clean_lastTradesInfo_df(self.eid)
  File "D:\Synced folder 2\tradex_opinionTrading\codes_2\lasttradesinfo.py", line 50, in clean_lastTradesInfo_df
    df = self._get_lastTradesInfo_df(id)
  File "D:\Synced folder 2\tradex_opinionTrading\codes_2\lasttradesinfo.py", line 19, in _get_lastTradesInfo_df
    resp = self.api_obj.tradex_caller("lastTradesInfo", body={"probeid": id})
  File "D:\Synced folder 2\tradex_opinionTrading\codes_2\api_caller.py", line 140, in tradex_caller
    raise Exception(f"MaxAttempt({retry_attempts}) exhausted. User{self.userid}")
Exception: MaxAttempt(3) exhausted. User0
ERROR:__main__:2022-12-25 23:00:23,204:MaxAttempt(3) exhausted. User0
Traceback (most recent call last):
  File "D:\Synced folder 2\tradex_opinionTrading\codes_2\venv\lib\site-packages\requests\models.py", line 971, in json
    return complexjson.loads(self.text, **kwargs)
  File "C:\Users\aniru\AppData\Local\Programs\Python\Python310\lib\json\__init__.py", line 346, in loads
    return _default_decoder.decode(s)
  File "C:\Users\aniru\AppData\Local\Programs\Python\Python310\lib\json\decoder.py", line 337, in decode
    obj, end = self.raw_decode(s, idx=_w(s, 0).end())
  File "C:\Users\aniru\AppData\Local\Programs\Python\Python310\lib\json\decoder.py", line 355, in raw_decode
    raise JSONDecodeError("Expecting value", s, err.value) from None
json.decoder.JSONDecodeError: Expecting value: line 1 column 1 (char 0)

During handling of the above exception, another exception occurred:

Traceback (most recent call last):
  File "D:\Synced folder 2\tradex_opinionTrading\codes_2\api_caller.py", line 118, in tradex_caller
    response = req.post(url, data=body, headers=headers).json()
  File "D:\Synced folder 2\tradex_opinionTrading\codes_2\venv\lib\site-packages\requests\models.py", line 975, in json
    raise RequestsJSONDecodeError(e.msg, e.doc, e.pos)
requests.exceptions.JSONDecodeError: Expecting value: line 1 column 1 (char 0)

During handling of the above exception, another exception occurred:

Traceback (most recent call last):
  File "D:\Synced folder 2\tradex_opinionTrading\codes_2\main_strategy_run.py", line 128, in <module>
    strat_obj_dict[j].update()
  File "D:\Synced folder 2\tradex_opinionTrading\codes_2\strat7.py", line 726, in update
    self._keep_a_check()
  File "D:\Synced folder 2\tradex_opinionTrading\codes_2\strat7.py", line 663, in _keep_a_check
    self.__scalp_side("N", trigger, pausebuy=False, pausesell=True)
  File "D:\Synced folder 2\tradex_opinionTrading\codes_2\strat7.py", line 301, in __scalp_side
    self.order.cancel_all_pending_buy("N", f"{trigger},NewBuyParams")
  File "D:\Synced folder 2\tradex_opinionTrading\codes_2\order.py", line 164, in cancel_all_pending_buy
    self._cancel_buy(message=message,
  File "D:\Synced folder 2\tradex_opinionTrading\codes_2\order.py", line 103, in _cancel_buy
    response = self.api_obj.tradex_caller(suffix, body)
  File "D:\Synced folder 2\tradex_opinionTrading\codes_2\api_caller.py", line 140, in tradex_caller
    raise Exception(f"MaxAttempt({retry_attempts}) exhausted. User{self.userid}")
Exception: MaxAttempt(3) exhausted. User0
ERROR:__main__:2022-12-25 23:01:10,284:MaxAttempt(3) exhausted. User0
Traceback (most recent call last):
  File "D:\Synced folder 2\tradex_opinionTrading\codes_2\venv\lib\site-packages\requests\models.py", line 971, in json
    return complexjson.loads(self.text, **kwargs)
  File "C:\Users\aniru\AppData\Local\Programs\Python\Python310\lib\json\__init__.py", line 346, in loads
    return _default_decoder.decode(s)
  File "C:\Users\aniru\AppData\Local\Programs\Python\Python310\lib\json\decoder.py", line 337, in decode
    obj, end = self.raw_decode(s, idx=_w(s, 0).end())
  File "C:\Users\aniru\AppData\Local\Programs\Python\Python310\lib\json\decoder.py", line 355, in raw_decode
    raise JSONDecodeError("Expecting value", s, err.value) from None
json.decoder.JSONDecodeError: Expecting value: line 1 column 1 (char 0)

During handling of the above exception, another exception occurred:

Traceback (most recent call last):
  File "D:\Synced folder 2\tradex_opinionTrading\codes_2\api_caller.py", line 118, in tradex_caller
    response = req.post(url, data=body, headers=headers).json()
  File "D:\Synced folder 2\tradex_opinionTrading\codes_2\venv\lib\site-packages\requests\models.py", line 975, in json
    raise RequestsJSONDecodeError(e.msg, e.doc, e.pos)
requests.exceptions.JSONDecodeError: Expecting value: line 1 column 1 (char 0)

During handling of the above exception, another exception occurred:

Traceback (most recent call last):
  File "D:\Synced folder 2\tradex_opinionTrading\codes_2\main_strategy_run.py", line 128, in <module>
    strat_obj_dict[j].update()
  File "D:\Synced folder 2\tradex_opinionTrading\codes_2\strat7.py", line 726, in update
    self._keep_a_check()
  File "D:\Synced folder 2\tradex_opinionTrading\codes_2\strat7.py", line 665, in _keep_a_check
    self.__scalp_side("N", trigger, pausebuy=False, pausesell=False)
  File "D:\Synced folder 2\tradex_opinionTrading\codes_2\strat7.py", line 304, in __scalp_side
    self.__send_buy_orders(f"{trigger},ScalpingNo,{set_priceqty_message}", "N", temp_price, temp_qty)
  File "D:\Synced folder 2\tradex_opinionTrading\codes_2\strat7.py", line 552, in __send_buy_orders
    self.order._buy(message, "N", price, qty)
  File "D:\Synced folder 2\tradex_opinionTrading\codes_2\order.py", line 38, in _buy
    response = self.api_obj.tradex_caller(suffix, body)
  File "D:\Synced folder 2\tradex_opinionTrading\codes_2\api_caller.py", line 140, in tradex_caller
    raise Exception(f"MaxAttempt({retry_attempts}) exhausted. User{self.userid}")
Exception: MaxAttempt(3) exhausted. User0
ERROR:__main__:2022-12-25 23:01:56,976:MaxAttempt(3) exhausted. User0
Traceback (most recent call last):
  File "D:\Synced folder 2\tradex_opinionTrading\codes_2\venv\lib\site-packages\requests\models.py", line 971, in json
    return complexjson.loads(self.text, **kwargs)
  File "C:\Users\aniru\AppData\Local\Programs\Python\Python310\lib\json\__init__.py", line 346, in loads
    return _default_decoder.decode(s)
  File "C:\Users\aniru\AppData\Local\Programs\Python\Python310\lib\json\decoder.py", line 337, in decode
    obj, end = self.raw_decode(s, idx=_w(s, 0).end())
  File "C:\Users\aniru\AppData\Local\Programs\Python\Python310\lib\json\decoder.py", line 355, in raw_decode
    raise JSONDecodeError("Expecting value", s, err.value) from None
json.decoder.JSONDecodeError: Expecting value: line 1 column 1 (char 0)

During handling of the above exception, another exception occurred:

Traceback (most recent call last):
  File "D:\Synced folder 2\tradex_opinionTrading\codes_2\api_caller.py", line 118, in tradex_caller
    response = req.post(url, data=body, headers=headers).json()
  File "D:\Synced folder 2\tradex_opinionTrading\codes_2\venv\lib\site-packages\requests\models.py", line 975, in json
    raise RequestsJSONDecodeError(e.msg, e.doc, e.pos)
requests.exceptions.JSONDecodeError: Expecting value: line 1 column 1 (char 0)

During handling of the above exception, another exception occurred:

Traceback (most recent call last):
  File "D:\Synced folder 2\tradex_opinionTrading\codes_2\main_strategy_run.py", line 128, in <module>
    strat_obj_dict[j].update()
  File "D:\Synced folder 2\tradex_opinionTrading\codes_2\strat7.py", line 726, in update
    self._keep_a_check()
  File "D:\Synced folder 2\tradex_opinionTrading\codes_2\strat7.py", line 665, in _keep_a_check
    self.__scalp_side("N", trigger, pausebuy=False, pausesell=False)
  File "D:\Synced folder 2\tradex_opinionTrading\codes_2\strat7.py", line 316, in __scalp_side
    self.__send_all_sell(f"{trigger},SellingBoughtQty,{set_priceqty_message}", "N", sell_price, sell_qty)
  File "D:\Synced folder 2\tradex_opinionTrading\codes_2\strat7.py", line 558, in __send_all_sell
    self.order._sell(message, "N", sell_price, sell_qty)
  File "D:\Synced folder 2\tradex_opinionTrading\codes_2\order.py", line 71, in _sell
    response = self.api_obj.tradex_caller(suffix, body)
  File "D:\Synced folder 2\tradex_opinionTrading\codes_2\api_caller.py", line 140, in tradex_caller
    raise Exception(f"MaxAttempt({retry_attempts}) exhausted. User{self.userid}")
Exception: MaxAttempt(3) exhausted. User0
