ERROR:__main__:2022-12-08 23:00:44,962:MaxAttempt(3) exhausted. User0
Traceback (most recent call last):
  File "D:\Synced folder 2\tradex_opinionTrading\codes_2\venv\lib\site-packages\requests\models.py", line 971, in json
    return complexjson.loads(self.text, **kwargs)
  File "C:\Users\aniru\AppData\Local\Programs\Python\Python310\lib\json\__init__.py", line 346, in loads
    return _default_decoder.decode(s)
  File "C:\Users\aniru\AppData\Local\Programs\Python\Python310\lib\json\decoder.py", line 337, in decode
    obj, end = self.raw_decode(s, idx=_w(s, 0).end())
  File "C:\Users\aniru\AppData\Local\Programs\Python\Python310\lib\json\decoder.py", line 355, in raw_decode
    raise JSONDecodeError("Expecting value", s, err.value) from None
json.decoder.JSONDecodeError: Expecting value: line 1 column 1 (char 0)

During handling of the above exception, another exception occurred:

Traceback (most recent call last):
  File "D:\Synced folder 2\tradex_opinionTrading\codes_2\api_caller.py", line 118, in tradex_caller
    response = req.post(url, data=body, headers=headers).json()
  File "D:\Synced folder 2\tradex_opinionTrading\codes_2\venv\lib\site-packages\requests\models.py", line 975, in json
    raise RequestsJSONDecodeError(e.msg, e.doc, e.pos)
requests.exceptions.JSONDecodeError: Expecting value: line 1 column 1 (char 0)

During handling of the above exception, another exception occurred:

Traceback (most recent call last):
  File "D:\Synced folder 2\tradex_opinionTrading\codes_2\main_strategy_run.py", line 128, in <module>
    strat_obj_dict[j].update()
  File "D:\Synced folder 2\tradex_opinionTrading\codes_2\strat7.py", line 611, in update
    self._keep_a_check()
  File "D:\Synced folder 2\tradex_opinionTrading\codes_2\strat7.py", line 526, in _keep_a_check
    self.__scalp_side("N", trigger, pausebuy=True)
  File "D:\Synced folder 2\tradex_opinionTrading\codes_2\strat7.py", line 282, in __scalp_side
    self.order.cancel_all_pending_buy("Y", f"{trigger},CancelOppSideOrders")
  File "D:\Synced folder 2\tradex_opinionTrading\codes_2\order.py", line 137, in cancel_all_pending_buy
    self._cancel_buy(message=message,
  File "D:\Synced folder 2\tradex_opinionTrading\codes_2\order.py", line 88, in _cancel_buy
    response = self.api_obj.tradex_caller(suffix, body)
  File "D:\Synced folder 2\tradex_opinionTrading\codes_2\api_caller.py", line 140, in tradex_caller
    raise Exception(f"MaxAttempt({retry_attempts}) exhausted. User{self.userid}")
Exception: MaxAttempt(3) exhausted. User0
ERROR:__main__:2022-12-08 23:01:26,227:MaxAttempt(3) exhausted. User0
Traceback (most recent call last):
  File "D:\Synced folder 2\tradex_opinionTrading\codes_2\venv\lib\site-packages\requests\models.py", line 971, in json
    return complexjson.loads(self.text, **kwargs)
  File "C:\Users\aniru\AppData\Local\Programs\Python\Python310\lib\json\__init__.py", line 346, in loads
    return _default_decoder.decode(s)
  File "C:\Users\aniru\AppData\Local\Programs\Python\Python310\lib\json\decoder.py", line 337, in decode
    obj, end = self.raw_decode(s, idx=_w(s, 0).end())
  File "C:\Users\aniru\AppData\Local\Programs\Python\Python310\lib\json\decoder.py", line 355, in raw_decode
    raise JSONDecodeError("Expecting value", s, err.value) from None
json.decoder.JSONDecodeError: Expecting value: line 1 column 1 (char 0)

During handling of the above exception, another exception occurred:

Traceback (most recent call last):
  File "D:\Synced folder 2\tradex_opinionTrading\codes_2\api_caller.py", line 118, in tradex_caller
    response = req.post(url, data=body, headers=headers).json()
  File "D:\Synced folder 2\tradex_opinionTrading\codes_2\venv\lib\site-packages\requests\models.py", line 975, in json
    raise RequestsJSONDecodeError(e.msg, e.doc, e.pos)
requests.exceptions.JSONDecodeError: Expecting value: line 1 column 1 (char 0)

During handling of the above exception, another exception occurred:

Traceback (most recent call last):
  File "D:\Synced folder 2\tradex_opinionTrading\codes_2\main_strategy_run.py", line 128, in <module>
    strat_obj_dict[j].update()
  File "D:\Synced folder 2\tradex_opinionTrading\codes_2\strat7.py", line 611, in update
    self._keep_a_check()
  File "D:\Synced folder 2\tradex_opinionTrading\codes_2\strat7.py", line 524, in _keep_a_check
    self.__scalp_side("N", trigger, pausebuy=False)
  File "D:\Synced folder 2\tradex_opinionTrading\codes_2\strat7.py", line 275, in __scalp_side
    self.__send_buy_orders(f"{trigger},ScalpingNo,{set_priceqty_message}", "N", temp_price, temp_qty)
  File "D:\Synced folder 2\tradex_opinionTrading\codes_2\strat7.py", line 482, in __send_buy_orders
    self.order._buy(message, "N", price, qty)
  File "D:\Synced folder 2\tradex_opinionTrading\codes_2\order.py", line 38, in _buy
    response = self.api_obj.tradex_caller(suffix, body)
  File "D:\Synced folder 2\tradex_opinionTrading\codes_2\api_caller.py", line 140, in tradex_caller
    raise Exception(f"MaxAttempt({retry_attempts}) exhausted. User{self.userid}")
Exception: MaxAttempt(3) exhausted. User0
