ERROR:__main__:2022-12-11 17:30:35,682:local variable 'portfolio_dict' referenced before assignment
Traceback (most recent call last):
  File "D:\Synced folder 2\tradex_opinionTrading\codes_2\main_strategy_run.py", line 128, in <module>
    strat_obj_dict[j].update()
  File "D:\Synced folder 2\tradex_opinionTrading\codes_2\strat7.py", line 613, in update
    self._strat_status_record()
  File "D:\Synced folder 2\tradex_opinionTrading\codes_2\strat7.py", line 235, in _strat_status_record
    data_dict["orders"] = self.mybet.get_event_holdings(self.event_id).to_dict("records")
  File "D:\Synced folder 2\tradex_opinionTrading\codes_2\mybets.py", line 44, in get_event_holdings
    port_dict = self._get_portfolio_dict()
  File "D:\Synced folder 2\tradex_opinionTrading\codes_2\mybets.py", line 41, in _get_portfolio_dict
    return portfolio_dict
UnboundLocalError: local variable 'portfolio_dict' referenced before assignment
ERROR:__main__:2022-12-11 20:25:03,563:local variable 'portfolio_dict' referenced before assignment
Traceback (most recent call last):
  File "D:\Synced folder 2\tradex_opinionTrading\codes_2\main_strategy_run.py", line 128, in <module>
    strat_obj_dict[j].update()
  File "D:\Synced folder 2\tradex_opinionTrading\codes_2\strat7.py", line 611, in update
    self._keep_a_check()
  File "D:\Synced folder 2\tradex_opinionTrading\codes_2\strat7.py", line 570, in _keep_a_check
    self.__scalp_side("N", trigger, pausebuy=False)
  File "D:\Synced folder 2\tradex_opinionTrading\codes_2\strat7.py", line 282, in __scalp_side
    self.order.cancel_all_pending_buy("Y", f"{trigger},CancelOppSideOrders")
  File "D:\Synced folder 2\tradex_opinionTrading\codes_2\order.py", line 129, in cancel_all_pending_buy
    df = self.mybet.get_event_holdings(self.event_id)
  File "D:\Synced folder 2\tradex_opinionTrading\codes_2\mybets.py", line 44, in get_event_holdings
    port_dict = self._get_portfolio_dict()
  File "D:\Synced folder 2\tradex_opinionTrading\codes_2\mybets.py", line 41, in _get_portfolio_dict
    return portfolio_dict
UnboundLocalError: local variable 'portfolio_dict' referenced before assignment
ERROR:__main__:2022-12-12 19:46:39,511:local variable 'portfolio_dict' referenced before assignment
Traceback (most recent call last):
  File "D:\Synced folder 2\tradex_opinionTrading\codes_2\main_strategy_run.py", line 128, in <module>
    strat_obj_dict[j].update()
  File "D:\Synced folder 2\tradex_opinionTrading\codes_2\strat7.py", line 608, in update
    self._set_qty()
  File "D:\Synced folder 2\tradex_opinionTrading\codes_2\strat7.py", line 329, in _set_qty
    self.my_avgbuy_price_yes, self.my_avgsell_price_yes, self.my_avgbuy_price_no, self.my_avgsell_price_no, self.falseavgbuyyes, self.falseavgbuyno = self.trans.get_avg_buysell_price(
  File "D:\Synced folder 2\tradex_opinionTrading\codes_2\transactions.py", line 177, in get_avg_buysell_price
    remove_no_qty, remove_no_amount = self._get_unfilled_qty_n_amount(event_id, "N")
  File "D:\Synced folder 2\tradex_opinionTrading\codes_2\transactions.py", line 256, in _get_unfilled_qty_n_amount
    bets_df = self.mybet.get_event_holdings(eid)
  File "D:\Synced folder 2\tradex_opinionTrading\codes_2\mybets.py", line 44, in get_event_holdings
    port_dict = self._get_portfolio_dict()
  File "D:\Synced folder 2\tradex_opinionTrading\codes_2\mybets.py", line 41, in _get_portfolio_dict
    return portfolio_dict
UnboundLocalError: local variable 'portfolio_dict' referenced before assignment
ERROR:__main__:2022-12-12 23:01:45,678:MaxAttempt(3) exhausted. User0
Traceback (most recent call last):
  File "D:\Synced folder 2\tradex_opinionTrading\codes_2\venv\lib\site-packages\requests\models.py", line 971, in json
    return complexjson.loads(self.text, **kwargs)
  File "C:\Users\aniru\AppData\Local\Programs\Python\Python310\lib\json\__init__.py", line 346, in loads
    return _default_decoder.decode(s)
  File "C:\Users\aniru\AppData\Local\Programs\Python\Python310\lib\json\decoder.py", line 337, in decode
    obj, end = self.raw_decode(s, idx=_w(s, 0).end())
  File "C:\Users\aniru\AppData\Local\Programs\Python\Python310\lib\json\decoder.py", line 355, in raw_decode
    raise JSONDecodeError("Expecting value", s, err.value) from None
json.decoder.JSONDecodeError: Expecting value: line 1 column 1 (char 0)

During handling of the above exception, another exception occurred:

Traceback (most recent call last):
  File "D:\Synced folder 2\tradex_opinionTrading\codes_2\api_caller.py", line 118, in tradex_caller
    response = req.post(url, data=body, headers=headers).json()
  File "D:\Synced folder 2\tradex_opinionTrading\codes_2\venv\lib\site-packages\requests\models.py", line 975, in json
    raise RequestsJSONDecodeError(e.msg, e.doc, e.pos)
requests.exceptions.JSONDecodeError: Expecting value: line 1 column 1 (char 0)

During handling of the above exception, another exception occurred:

Traceback (most recent call last):
  File "D:\Synced folder 2\tradex_opinionTrading\codes_2\main_strategy_run.py", line 128, in <module>
    strat_obj_dict[j].update()
  File "D:\Synced folder 2\tradex_opinionTrading\codes_2\strat7.py", line 611, in update
    self._keep_a_check()
  File "D:\Synced folder 2\tradex_opinionTrading\codes_2\strat7.py", line 524, in _keep_a_check
    self.__scalp_side("N", trigger, pausebuy=False)
  File "D:\Synced folder 2\tradex_opinionTrading\codes_2\strat7.py", line 275, in __scalp_side
    self.__send_buy_orders(f"{trigger},ScalpingNo,{set_priceqty_message}", "N", temp_price, temp_qty)
  File "D:\Synced folder 2\tradex_opinionTrading\codes_2\strat7.py", line 482, in __send_buy_orders
    self.order._buy(message, "N", price, qty)
  File "D:\Synced folder 2\tradex_opinionTrading\codes_2\order.py", line 38, in _buy
    response = self.api_obj.tradex_caller(suffix, body)
  File "D:\Synced folder 2\tradex_opinionTrading\codes_2\api_caller.py", line 140, in tradex_caller
    raise Exception(f"MaxAttempt({retry_attempts}) exhausted. User{self.userid}")
Exception: MaxAttempt(3) exhausted. User0
ERROR:__main__:2022-12-13 15:52:18,441:'title'
Traceback (most recent call last):
  File "D:\Synced folder 2\tradex_opinionTrading\codes_2\main_strategy_run.py", line 115, in <module>
    strat_obj_dict[i].initialise()
  File "D:\Synced folder 2\tradex_opinionTrading\codes_2\strat7.py", line 577, in initialise
    self.priceatri.initialise_priceatri()
  File "D:\Synced folder 2\tradex_opinionTrading\codes_2\price_attributes.py", line 90, in initialise_priceatri
    self.initialise_event()
  File "D:\Synced folder 2\tradex_opinionTrading\codes_2\event_params.py", line 22, in initialise_event
    self.title = static_data["title"]
KeyError: 'title'
ERROR:__main__:2022-12-13 15:52:18,653:fromisoformat: argument must be str
Traceback (most recent call last):
  File "D:\Synced folder 2\tradex_opinionTrading\codes_2\main_strategy_run.py", line 124, in <module>
    while dt.datetime.now() <= dt.datetime.fromisoformat(strat_obj_dict[i].priceatri.ends_at):
TypeError: fromisoformat: argument must be str
ERROR:__main__:2022-12-13 16:02:46,022:'title'
Traceback (most recent call last):
  File "D:\Synced folder 2\tradex_opinionTrading\codes_2\main_strategy_run.py", line 115, in <module>
    strat_obj_dict[i].initialise()
  File "D:\Synced folder 2\tradex_opinionTrading\codes_2\strat7.py", line 577, in initialise
    self.priceatri.initialise_priceatri()
  File "D:\Synced folder 2\tradex_opinionTrading\codes_2\price_attributes.py", line 90, in initialise_priceatri
    self.initialise_event()
  File "D:\Synced folder 2\tradex_opinionTrading\codes_2\event_params.py", line 22, in initialise_event
    self.title = static_data["title"]
KeyError: 'title'
ERROR:__main__:2022-12-13 16:02:46,382:'title'
Traceback (most recent call last):
  File "D:\Synced folder 2\tradex_opinionTrading\codes_2\main_strategy_run.py", line 115, in <module>
    strat_obj_dict[i].initialise()
  File "D:\Synced folder 2\tradex_opinionTrading\codes_2\strat7.py", line 577, in initialise
    self.priceatri.initialise_priceatri()
  File "D:\Synced folder 2\tradex_opinionTrading\codes_2\price_attributes.py", line 90, in initialise_priceatri
    self.initialise_event()
  File "D:\Synced folder 2\tradex_opinionTrading\codes_2\event_params.py", line 22, in initialise_event
    self.title = static_data["title"]
KeyError: 'title'
ERROR:__main__:2022-12-13 16:02:46,434:'title'
Traceback (most recent call last):
  File "D:\Synced folder 2\tradex_opinionTrading\codes_2\main_strategy_run.py", line 115, in <module>
    strat_obj_dict[i].initialise()
  File "D:\Synced folder 2\tradex_opinionTrading\codes_2\strat7.py", line 577, in initialise
    self.priceatri.initialise_priceatri()
  File "D:\Synced folder 2\tradex_opinionTrading\codes_2\price_attributes.py", line 90, in initialise_priceatri
    self.initialise_event()
  File "D:\Synced folder 2\tradex_opinionTrading\codes_2\event_params.py", line 22, in initialise_event
    self.title = static_data["title"]
KeyError: 'title'
ERROR:__main__:2022-12-13 16:02:46,441:fromisoformat: argument must be str
Traceback (most recent call last):
  File "D:\Synced folder 2\tradex_opinionTrading\codes_2\main_strategy_run.py", line 124, in <module>
    while dt.datetime.now() <= dt.datetime.fromisoformat(strat_obj_dict[i].priceatri.ends_at):
TypeError: fromisoformat: argument must be str
ERROR:__main__:2022-12-13 16:07:52,451:'title'
Traceback (most recent call last):
  File "D:\Synced folder 2\tradex_opinionTrading\codes_2\main_strategy_run.py", line 115, in <module>
    strat_obj_dict[i].initialise()
  File "D:\Synced folder 2\tradex_opinionTrading\codes_2\strat7.py", line 577, in initialise
    self.priceatri.initialise_priceatri()
  File "D:\Synced folder 2\tradex_opinionTrading\codes_2\price_attributes.py", line 90, in initialise_priceatri
    self.initialise_event()
  File "D:\Synced folder 2\tradex_opinionTrading\codes_2\event_params.py", line 22, in initialise_event
    self.title = static_data["title"]
KeyError: 'title'
ERROR:__main__:2022-12-13 16:07:52,460:fromisoformat: argument must be str
Traceback (most recent call last):
  File "D:\Synced folder 2\tradex_opinionTrading\codes_2\main_strategy_run.py", line 124, in <module>
    while dt.datetime.now() <= dt.datetime.fromisoformat(strat_obj_dict[i].priceatri.ends_at):
TypeError: fromisoformat: argument must be str
ERROR:__main__:2022-12-14 18:08:16,651:name 'fprice_changed' is not defined
Traceback (most recent call last):
  File "D:\Synced folder 2\tradex_opinionTrading\codes_2\main_strategy_run.py", line 128, in <module>
    strat_obj_dict[j].update()
  File "D:\Synced folder 2\tradex_opinionTrading\codes_2\strat7.py", line 612, in update
    self._keep_a_check()
  File "D:\Synced folder 2\tradex_opinionTrading\codes_2\strat7.py", line 553, in _keep_a_check
    elif fprice_changed:
NameError: name 'fprice_changed' is not defined
ERROR:__main__:2022-12-14 18:08:35,033:name 'fprice_changed' is not defined
Traceback (most recent call last):
  File "D:\Synced folder 2\tradex_opinionTrading\codes_2\main_strategy_run.py", line 128, in <module>
    strat_obj_dict[j].update()
  File "D:\Synced folder 2\tradex_opinionTrading\codes_2\strat7.py", line 612, in update
    self._keep_a_check()
  File "D:\Synced folder 2\tradex_opinionTrading\codes_2\strat7.py", line 553, in _keep_a_check
    elif fprice_changed:
NameError: name 'fprice_changed' is not defined
ERROR:__main__:2022-12-14 18:08:53,149:name 'fprice_changed' is not defined
Traceback (most recent call last):
  File "D:\Synced folder 2\tradex_opinionTrading\codes_2\main_strategy_run.py", line 128, in <module>
    strat_obj_dict[j].update()
  File "D:\Synced folder 2\tradex_opinionTrading\codes_2\strat7.py", line 612, in update
    self._keep_a_check()
  File "D:\Synced folder 2\tradex_opinionTrading\codes_2\strat7.py", line 553, in _keep_a_check
    elif fprice_changed:
NameError: name 'fprice_changed' is not defined
ERROR:__main__:2022-12-14 18:09:22,118:name 'fprice_changed' is not defined
Traceback (most recent call last):
  File "D:\Synced folder 2\tradex_opinionTrading\codes_2\main_strategy_run.py", line 128, in <module>
    strat_obj_dict[j].update()
  File "D:\Synced folder 2\tradex_opinionTrading\codes_2\strat7.py", line 612, in update
    self._keep_a_check()
  File "D:\Synced folder 2\tradex_opinionTrading\codes_2\strat7.py", line 553, in _keep_a_check
    elif fprice_changed:
NameError: name 'fprice_changed' is not defined
ERROR:__main__:2022-12-14 20:17:07,835:local variable 'portfolio_dict' referenced before assignment
Traceback (most recent call last):
  File "D:\Synced folder 2\tradex_opinionTrading\codes_2\main_strategy_run.py", line 128, in <module>
    strat_obj_dict[j].update()
  File "D:\Synced folder 2\tradex_opinionTrading\codes_2\strat7.py", line 611, in update
    self._set_qty()
  File "D:\Synced folder 2\tradex_opinionTrading\codes_2\strat7.py", line 333, in _set_qty
    self.my_lastbuy_price_yes, self.my_lastbuy_price_no = self.mybet.get_buy_price(self.event_id)
  File "D:\Synced folder 2\tradex_opinionTrading\codes_2\mybets.py", line 120, in get_buy_price
    df = self.get_event_holdings(id)
  File "D:\Synced folder 2\tradex_opinionTrading\codes_2\mybets.py", line 44, in get_event_holdings
    port_dict = self._get_portfolio_dict()
  File "D:\Synced folder 2\tradex_opinionTrading\codes_2\mybets.py", line 41, in _get_portfolio_dict
    return portfolio_dict
UnboundLocalError: local variable 'portfolio_dict' referenced before assignment
ERROR:__main__:2022-12-14 20:39:23,963:MaxAttempt(3) exhausted. User0
Traceback (most recent call last):
  File "D:\Synced folder 2\tradex_opinionTrading\codes_2\venv\lib\site-packages\urllib3\connection.py", line 174, in _new_conn
    conn = connection.create_connection(
  File "D:\Synced folder 2\tradex_opinionTrading\codes_2\venv\lib\site-packages\urllib3\util\connection.py", line 72, in create_connection
    for res in socket.getaddrinfo(host, port, family, socket.SOCK_STREAM):
  File "C:\Users\aniru\AppData\Local\Programs\Python\Python310\lib\socket.py", line 955, in getaddrinfo
    for res in _socket.getaddrinfo(host, port, family, type, proto, flags):
socket.gaierror: [Errno 11001] getaddrinfo failed

During handling of the above exception, another exception occurred:

Traceback (most recent call last):
  File "D:\Synced folder 2\tradex_opinionTrading\codes_2\venv\lib\site-packages\urllib3\connectionpool.py", line 703, in urlopen
    httplib_response = self._make_request(
  File "D:\Synced folder 2\tradex_opinionTrading\codes_2\venv\lib\site-packages\urllib3\connectionpool.py", line 386, in _make_request
    self._validate_conn(conn)
  File "D:\Synced folder 2\tradex_opinionTrading\codes_2\venv\lib\site-packages\urllib3\connectionpool.py", line 1042, in _validate_conn
    conn.connect()
  File "D:\Synced folder 2\tradex_opinionTrading\codes_2\venv\lib\site-packages\urllib3\connection.py", line 358, in connect
    self.sock = conn = self._new_conn()
  File "D:\Synced folder 2\tradex_opinionTrading\codes_2\venv\lib\site-packages\urllib3\connection.py", line 186, in _new_conn
    raise NewConnectionError(
urllib3.exceptions.NewConnectionError: <urllib3.connection.HTTPSConnection object at 0x000001E28D1D1A80>: Failed to establish a new connection: [Errno 11001] getaddrinfo failed

During handling of the above exception, another exception occurred:

Traceback (most recent call last):
  File "D:\Synced folder 2\tradex_opinionTrading\codes_2\venv\lib\site-packages\requests\adapters.py", line 489, in send
    resp = conn.urlopen(
  File "D:\Synced folder 2\tradex_opinionTrading\codes_2\venv\lib\site-packages\urllib3\connectionpool.py", line 787, in urlopen
    retries = retries.increment(
  File "D:\Synced folder 2\tradex_opinionTrading\codes_2\venv\lib\site-packages\urllib3\util\retry.py", line 592, in increment
    raise MaxRetryError(_pool, url, error or ResponseError(cause))
urllib3.exceptions.MaxRetryError: HTTPSConnectionPool(host='api.theox.co', port=443): Max retries exceeded with url: /v2/mybetsv2 (Caused by NewConnectionError('<urllib3.connection.HTTPSConnection object at 0x000001E28D1D1A80>: Failed to establish a new connection: [Errno 11001] getaddrinfo failed'))

During handling of the above exception, another exception occurred:

Traceback (most recent call last):
  File "D:\Synced folder 2\tradex_opinionTrading\codes_2\api_caller.py", line 118, in tradex_caller
    response = req.post(url, data=body, headers=headers).json()
  File "D:\Synced folder 2\tradex_opinionTrading\codes_2\venv\lib\site-packages\requests\api.py", line 115, in post
    return request("post", url, data=data, json=json, **kwargs)
  File "D:\Synced folder 2\tradex_opinionTrading\codes_2\venv\lib\site-packages\requests\api.py", line 59, in request
    return session.request(method=method, url=url, **kwargs)
  File "D:\Synced folder 2\tradex_opinionTrading\codes_2\venv\lib\site-packages\requests\sessions.py", line 587, in request
    resp = self.send(prep, **send_kwargs)
  File "D:\Synced folder 2\tradex_opinionTrading\codes_2\venv\lib\site-packages\requests\sessions.py", line 701, in send
    r = adapter.send(request, **kwargs)
  File "D:\Synced folder 2\tradex_opinionTrading\codes_2\venv\lib\site-packages\requests\adapters.py", line 565, in send
    raise ConnectionError(e, request=request)
requests.exceptions.ConnectionError: HTTPSConnectionPool(host='api.theox.co', port=443): Max retries exceeded with url: /v2/mybetsv2 (Caused by NewConnectionError('<urllib3.connection.HTTPSConnection object at 0x000001E28D1D1A80>: Failed to establish a new connection: [Errno 11001] getaddrinfo failed'))

During handling of the above exception, another exception occurred:

Traceback (most recent call last):
  File "D:\Synced folder 2\tradex_opinionTrading\codes_2\main_strategy_run.py", line 128, in <module>
    strat_obj_dict[j].update()
  File "D:\Synced folder 2\tradex_opinionTrading\codes_2\strat7.py", line 614, in update
    self._keep_a_check()
  File "D:\Synced folder 2\tradex_opinionTrading\codes_2\strat7.py", line 568, in _keep_a_check
    self.__scalp_side("Y", trigger, pausebuy=False)
  File "D:\Synced folder 2\tradex_opinionTrading\codes_2\strat7.py", line 264, in __scalp_side
    self.order.cancel_all_pending_buy("N", f"{trigger},CancelOppSideOrders")
  File "D:\Synced folder 2\tradex_opinionTrading\codes_2\order.py", line 129, in cancel_all_pending_buy
    df = self.mybet.get_event_holdings(self.event_id)
  File "D:\Synced folder 2\tradex_opinionTrading\codes_2\mybets.py", line 44, in get_event_holdings
    port_dict = self._get_portfolio_dict()
  File "D:\Synced folder 2\tradex_opinionTrading\codes_2\mybets.py", line 28, in _get_portfolio_dict
    resp = self.api_obj.tradex_caller("mybetsv2", {"eventsStatus": "'A','F'"})
  File "D:\Synced folder 2\tradex_opinionTrading\codes_2\api_caller.py", line 140, in tradex_caller
    raise Exception(f"MaxAttempt({retry_attempts}) exhausted. User{self.userid}")
Exception: MaxAttempt(3) exhausted. User0
ERROR:__main__:2022-12-14 20:40:04,288:MaxAttempt(3) exhausted. User0
Traceback (most recent call last):
  File "D:\Synced folder 2\tradex_opinionTrading\codes_2\venv\lib\site-packages\urllib3\connection.py", line 174, in _new_conn
    conn = connection.create_connection(
  File "D:\Synced folder 2\tradex_opinionTrading\codes_2\venv\lib\site-packages\urllib3\util\connection.py", line 72, in create_connection
    for res in socket.getaddrinfo(host, port, family, socket.SOCK_STREAM):
  File "C:\Users\aniru\AppData\Local\Programs\Python\Python310\lib\socket.py", line 955, in getaddrinfo
    for res in _socket.getaddrinfo(host, port, family, type, proto, flags):
socket.gaierror: [Errno 11001] getaddrinfo failed

During handling of the above exception, another exception occurred:

Traceback (most recent call last):
  File "D:\Synced folder 2\tradex_opinionTrading\codes_2\venv\lib\site-packages\urllib3\connectionpool.py", line 703, in urlopen
    httplib_response = self._make_request(
  File "D:\Synced folder 2\tradex_opinionTrading\codes_2\venv\lib\site-packages\urllib3\connectionpool.py", line 386, in _make_request
    self._validate_conn(conn)
  File "D:\Synced folder 2\tradex_opinionTrading\codes_2\venv\lib\site-packages\urllib3\connectionpool.py", line 1042, in _validate_conn
    conn.connect()
  File "D:\Synced folder 2\tradex_opinionTrading\codes_2\venv\lib\site-packages\urllib3\connection.py", line 358, in connect
    self.sock = conn = self._new_conn()
  File "D:\Synced folder 2\tradex_opinionTrading\codes_2\venv\lib\site-packages\urllib3\connection.py", line 186, in _new_conn
    raise NewConnectionError(
urllib3.exceptions.NewConnectionError: <urllib3.connection.HTTPSConnection object at 0x000001E28D1D2770>: Failed to establish a new connection: [Errno 11001] getaddrinfo failed

During handling of the above exception, another exception occurred:

Traceback (most recent call last):
  File "D:\Synced folder 2\tradex_opinionTrading\codes_2\venv\lib\site-packages\requests\adapters.py", line 489, in send
    resp = conn.urlopen(
  File "D:\Synced folder 2\tradex_opinionTrading\codes_2\venv\lib\site-packages\urllib3\connectionpool.py", line 787, in urlopen
    retries = retries.increment(
  File "D:\Synced folder 2\tradex_opinionTrading\codes_2\venv\lib\site-packages\urllib3\util\retry.py", line 592, in increment
    raise MaxRetryError(_pool, url, error or ResponseError(cause))
urllib3.exceptions.MaxRetryError: HTTPSConnectionPool(host='api.theox.co', port=443): Max retries exceeded with url: /v2/lastTradesInfo (Caused by NewConnectionError('<urllib3.connection.HTTPSConnection object at 0x000001E28D1D2770>: Failed to establish a new connection: [Errno 11001] getaddrinfo failed'))

During handling of the above exception, another exception occurred:

Traceback (most recent call last):
  File "D:\Synced folder 2\tradex_opinionTrading\codes_2\api_caller.py", line 118, in tradex_caller
    response = req.post(url, data=body, headers=headers).json()
  File "D:\Synced folder 2\tradex_opinionTrading\codes_2\venv\lib\site-packages\requests\api.py", line 115, in post
    return request("post", url, data=data, json=json, **kwargs)
  File "D:\Synced folder 2\tradex_opinionTrading\codes_2\venv\lib\site-packages\requests\api.py", line 59, in request
    return session.request(method=method, url=url, **kwargs)
  File "D:\Synced folder 2\tradex_opinionTrading\codes_2\venv\lib\site-packages\requests\sessions.py", line 587, in request
    resp = self.send(prep, **send_kwargs)
  File "D:\Synced folder 2\tradex_opinionTrading\codes_2\venv\lib\site-packages\requests\sessions.py", line 701, in send
    r = adapter.send(request, **kwargs)
  File "D:\Synced folder 2\tradex_opinionTrading\codes_2\venv\lib\site-packages\requests\adapters.py", line 565, in send
    raise ConnectionError(e, request=request)
requests.exceptions.ConnectionError: HTTPSConnectionPool(host='api.theox.co', port=443): Max retries exceeded with url: /v2/lastTradesInfo (Caused by NewConnectionError('<urllib3.connection.HTTPSConnection object at 0x000001E28D1D2770>: Failed to establish a new connection: [Errno 11001] getaddrinfo failed'))

During handling of the above exception, another exception occurred:

Traceback (most recent call last):
  File "D:\Synced folder 2\tradex_opinionTrading\codes_2\main_strategy_run.py", line 128, in <module>
    strat_obj_dict[j].update()
  File "D:\Synced folder 2\tradex_opinionTrading\codes_2\strat7.py", line 602, in update
    self.priceatri.update_priceatri()
  File "D:\Synced folder 2\tradex_opinionTrading\codes_2\price_attributes.py", line 98, in update_priceatri
    self.update_event()
  File "D:\Synced folder 2\tradex_opinionTrading\codes_2\event_params.py", line 31, in update_event
    self.last_executed_trades = self.lti.clean_lastTradesInfo_df(self.eid)
  File "D:\Synced folder 2\tradex_opinionTrading\codes_2\lasttradesinfo.py", line 50, in clean_lastTradesInfo_df
    df = self._get_lastTradesInfo_df(id)
  File "D:\Synced folder 2\tradex_opinionTrading\codes_2\lasttradesinfo.py", line 19, in _get_lastTradesInfo_df
    resp = self.api_obj.tradex_caller("lastTradesInfo", body={"probeid": id})
  File "D:\Synced folder 2\tradex_opinionTrading\codes_2\api_caller.py", line 140, in tradex_caller
    raise Exception(f"MaxAttempt({retry_attempts}) exhausted. User{self.userid}")
Exception: MaxAttempt(3) exhausted. User0
ERROR:__main__:2022-12-14 20:40:44,718:MaxAttempt(3) exhausted. User0
Traceback (most recent call last):
  File "D:\Synced folder 2\tradex_opinionTrading\codes_2\venv\lib\site-packages\urllib3\connection.py", line 174, in _new_conn
    conn = connection.create_connection(
  File "D:\Synced folder 2\tradex_opinionTrading\codes_2\venv\lib\site-packages\urllib3\util\connection.py", line 72, in create_connection
    for res in socket.getaddrinfo(host, port, family, socket.SOCK_STREAM):
  File "C:\Users\aniru\AppData\Local\Programs\Python\Python310\lib\socket.py", line 955, in getaddrinfo
    for res in _socket.getaddrinfo(host, port, family, type, proto, flags):
socket.gaierror: [Errno 11001] getaddrinfo failed

During handling of the above exception, another exception occurred:

Traceback (most recent call last):
  File "D:\Synced folder 2\tradex_opinionTrading\codes_2\venv\lib\site-packages\urllib3\connectionpool.py", line 703, in urlopen
    httplib_response = self._make_request(
  File "D:\Synced folder 2\tradex_opinionTrading\codes_2\venv\lib\site-packages\urllib3\connectionpool.py", line 386, in _make_request
    self._validate_conn(conn)
  File "D:\Synced folder 2\tradex_opinionTrading\codes_2\venv\lib\site-packages\urllib3\connectionpool.py", line 1042, in _validate_conn
    conn.connect()
  File "D:\Synced folder 2\tradex_opinionTrading\codes_2\venv\lib\site-packages\urllib3\connection.py", line 358, in connect
    self.sock = conn = self._new_conn()
  File "D:\Synced folder 2\tradex_opinionTrading\codes_2\venv\lib\site-packages\urllib3\connection.py", line 186, in _new_conn
    raise NewConnectionError(
urllib3.exceptions.NewConnectionError: <urllib3.connection.HTTPSConnection object at 0x000001E28D1D2290>: Failed to establish a new connection: [Errno 11001] getaddrinfo failed

During handling of the above exception, another exception occurred:

Traceback (most recent call last):
  File "D:\Synced folder 2\tradex_opinionTrading\codes_2\venv\lib\site-packages\requests\adapters.py", line 489, in send
    resp = conn.urlopen(
  File "D:\Synced folder 2\tradex_opinionTrading\codes_2\venv\lib\site-packages\urllib3\connectionpool.py", line 787, in urlopen
    retries = retries.increment(
  File "D:\Synced folder 2\tradex_opinionTrading\codes_2\venv\lib\site-packages\urllib3\util\retry.py", line 592, in increment
    raise MaxRetryError(_pool, url, error or ResponseError(cause))
urllib3.exceptions.MaxRetryError: HTTPSConnectionPool(host='api.theox.co', port=443): Max retries exceeded with url: /v2/lastTradesInfo (Caused by NewConnectionError('<urllib3.connection.HTTPSConnection object at 0x000001E28D1D2290>: Failed to establish a new connection: [Errno 11001] getaddrinfo failed'))

During handling of the above exception, another exception occurred:

Traceback (most recent call last):
  File "D:\Synced folder 2\tradex_opinionTrading\codes_2\api_caller.py", line 118, in tradex_caller
    response = req.post(url, data=body, headers=headers).json()
  File "D:\Synced folder 2\tradex_opinionTrading\codes_2\venv\lib\site-packages\requests\api.py", line 115, in post
    return request("post", url, data=data, json=json, **kwargs)
  File "D:\Synced folder 2\tradex_opinionTrading\codes_2\venv\lib\site-packages\requests\api.py", line 59, in request
    return session.request(method=method, url=url, **kwargs)
  File "D:\Synced folder 2\tradex_opinionTrading\codes_2\venv\lib\site-packages\requests\sessions.py", line 587, in request
    resp = self.send(prep, **send_kwargs)
  File "D:\Synced folder 2\tradex_opinionTrading\codes_2\venv\lib\site-packages\requests\sessions.py", line 701, in send
    r = adapter.send(request, **kwargs)
  File "D:\Synced folder 2\tradex_opinionTrading\codes_2\venv\lib\site-packages\requests\adapters.py", line 565, in send
    raise ConnectionError(e, request=request)
requests.exceptions.ConnectionError: HTTPSConnectionPool(host='api.theox.co', port=443): Max retries exceeded with url: /v2/lastTradesInfo (Caused by NewConnectionError('<urllib3.connection.HTTPSConnection object at 0x000001E28D1D2290>: Failed to establish a new connection: [Errno 11001] getaddrinfo failed'))

During handling of the above exception, another exception occurred:

Traceback (most recent call last):
  File "D:\Synced folder 2\tradex_opinionTrading\codes_2\main_strategy_run.py", line 128, in <module>
    strat_obj_dict[j].update()
  File "D:\Synced folder 2\tradex_opinionTrading\codes_2\strat7.py", line 602, in update
    self.priceatri.update_priceatri()
  File "D:\Synced folder 2\tradex_opinionTrading\codes_2\price_attributes.py", line 98, in update_priceatri
    self.update_event()
  File "D:\Synced folder 2\tradex_opinionTrading\codes_2\event_params.py", line 31, in update_event
    self.last_executed_trades = self.lti.clean_lastTradesInfo_df(self.eid)
  File "D:\Synced folder 2\tradex_opinionTrading\codes_2\lasttradesinfo.py", line 50, in clean_lastTradesInfo_df
    df = self._get_lastTradesInfo_df(id)
  File "D:\Synced folder 2\tradex_opinionTrading\codes_2\lasttradesinfo.py", line 19, in _get_lastTradesInfo_df
    resp = self.api_obj.tradex_caller("lastTradesInfo", body={"probeid": id})
  File "D:\Synced folder 2\tradex_opinionTrading\codes_2\api_caller.py", line 140, in tradex_caller
    raise Exception(f"MaxAttempt({retry_attempts}) exhausted. User{self.userid}")
Exception: MaxAttempt(3) exhausted. User0
ERROR:__main__:2022-12-14 20:41:58,165:MaxAttempt(3) exhausted. User0
Traceback (most recent call last):
  File "D:\Synced folder 2\tradex_opinionTrading\codes_2\venv\lib\site-packages\urllib3\connection.py", line 174, in _new_conn
    conn = connection.create_connection(
  File "D:\Synced folder 2\tradex_opinionTrading\codes_2\venv\lib\site-packages\urllib3\util\connection.py", line 72, in create_connection
    for res in socket.getaddrinfo(host, port, family, socket.SOCK_STREAM):
  File "C:\Users\aniru\AppData\Local\Programs\Python\Python310\lib\socket.py", line 955, in getaddrinfo
    for res in _socket.getaddrinfo(host, port, family, type, proto, flags):
socket.gaierror: [Errno 11001] getaddrinfo failed

During handling of the above exception, another exception occurred:

Traceback (most recent call last):
  File "D:\Synced folder 2\tradex_opinionTrading\codes_2\venv\lib\site-packages\urllib3\connectionpool.py", line 703, in urlopen
    httplib_response = self._make_request(
  File "D:\Synced folder 2\tradex_opinionTrading\codes_2\venv\lib\site-packages\urllib3\connectionpool.py", line 386, in _make_request
    self._validate_conn(conn)
  File "D:\Synced folder 2\tradex_opinionTrading\codes_2\venv\lib\site-packages\urllib3\connectionpool.py", line 1042, in _validate_conn
    conn.connect()
  File "D:\Synced folder 2\tradex_opinionTrading\codes_2\venv\lib\site-packages\urllib3\connection.py", line 358, in connect
    self.sock = conn = self._new_conn()
  File "D:\Synced folder 2\tradex_opinionTrading\codes_2\venv\lib\site-packages\urllib3\connection.py", line 186, in _new_conn
    raise NewConnectionError(
urllib3.exceptions.NewConnectionError: <urllib3.connection.HTTPSConnection object at 0x000001E28D2A4610>: Failed to establish a new connection: [Errno 11001] getaddrinfo failed

During handling of the above exception, another exception occurred:

Traceback (most recent call last):
  File "D:\Synced folder 2\tradex_opinionTrading\codes_2\venv\lib\site-packages\requests\adapters.py", line 489, in send
    resp = conn.urlopen(
  File "D:\Synced folder 2\tradex_opinionTrading\codes_2\venv\lib\site-packages\urllib3\connectionpool.py", line 787, in urlopen
    retries = retries.increment(
  File "D:\Synced folder 2\tradex_opinionTrading\codes_2\venv\lib\site-packages\urllib3\util\retry.py", line 592, in increment
    raise MaxRetryError(_pool, url, error or ResponseError(cause))
urllib3.exceptions.MaxRetryError: HTTPSConnectionPool(host='api.theox.co', port=443): Max retries exceeded with url: /v2/lastTradesInfo (Caused by NewConnectionError('<urllib3.connection.HTTPSConnection object at 0x000001E28D2A4610>: Failed to establish a new connection: [Errno 11001] getaddrinfo failed'))

During handling of the above exception, another exception occurred:

Traceback (most recent call last):
  File "D:\Synced folder 2\tradex_opinionTrading\codes_2\api_caller.py", line 118, in tradex_caller
    response = req.post(url, data=body, headers=headers).json()
  File "D:\Synced folder 2\tradex_opinionTrading\codes_2\venv\lib\site-packages\requests\api.py", line 115, in post
    return request("post", url, data=data, json=json, **kwargs)
  File "D:\Synced folder 2\tradex_opinionTrading\codes_2\venv\lib\site-packages\requests\api.py", line 59, in request
    return session.request(method=method, url=url, **kwargs)
  File "D:\Synced folder 2\tradex_opinionTrading\codes_2\venv\lib\site-packages\requests\sessions.py", line 587, in request
    resp = self.send(prep, **send_kwargs)
  File "D:\Synced folder 2\tradex_opinionTrading\codes_2\venv\lib\site-packages\requests\sessions.py", line 701, in send
    r = adapter.send(request, **kwargs)
  File "D:\Synced folder 2\tradex_opinionTrading\codes_2\venv\lib\site-packages\requests\adapters.py", line 565, in send
    raise ConnectionError(e, request=request)
requests.exceptions.ConnectionError: HTTPSConnectionPool(host='api.theox.co', port=443): Max retries exceeded with url: /v2/lastTradesInfo (Caused by NewConnectionError('<urllib3.connection.HTTPSConnection object at 0x000001E28D2A4610>: Failed to establish a new connection: [Errno 11001] getaddrinfo failed'))

During handling of the above exception, another exception occurred:

Traceback (most recent call last):
  File "D:\Synced folder 2\tradex_opinionTrading\codes_2\main_strategy_run.py", line 128, in <module>
    strat_obj_dict[j].update()
  File "D:\Synced folder 2\tradex_opinionTrading\codes_2\strat7.py", line 602, in update
    self.priceatri.update_priceatri()
  File "D:\Synced folder 2\tradex_opinionTrading\codes_2\price_attributes.py", line 98, in update_priceatri
    self.update_event()
  File "D:\Synced folder 2\tradex_opinionTrading\codes_2\event_params.py", line 31, in update_event
    self.last_executed_trades = self.lti.clean_lastTradesInfo_df(self.eid)
  File "D:\Synced folder 2\tradex_opinionTrading\codes_2\lasttradesinfo.py", line 50, in clean_lastTradesInfo_df
    df = self._get_lastTradesInfo_df(id)
  File "D:\Synced folder 2\tradex_opinionTrading\codes_2\lasttradesinfo.py", line 19, in _get_lastTradesInfo_df
    resp = self.api_obj.tradex_caller("lastTradesInfo", body={"probeid": id})
  File "D:\Synced folder 2\tradex_opinionTrading\codes_2\api_caller.py", line 140, in tradex_caller
    raise Exception(f"MaxAttempt({retry_attempts}) exhausted. User{self.userid}")
Exception: MaxAttempt(3) exhausted. User0
ERROR:__main__:2022-12-14 22:15:14,764:local variable 'portfolio_dict' referenced before assignment
Traceback (most recent call last):
  File "D:\Synced folder 2\tradex_opinionTrading\codes_2\main_strategy_run.py", line 128, in <module>
    strat_obj_dict[j].update()
  File "D:\Synced folder 2\tradex_opinionTrading\codes_2\strat7.py", line 614, in update
    self._keep_a_check()
  File "D:\Synced folder 2\tradex_opinionTrading\codes_2\strat7.py", line 519, in _keep_a_check
    self.__scalp_side("Y", trigger, pausebuy=False)
  File "D:\Synced folder 2\tradex_opinionTrading\codes_2\strat7.py", line 264, in __scalp_side
    self.order.cancel_all_pending_buy("N", f"{trigger},CancelOppSideOrders")
  File "D:\Synced folder 2\tradex_opinionTrading\codes_2\order.py", line 129, in cancel_all_pending_buy
    df = self.mybet.get_event_holdings(self.event_id)
  File "D:\Synced folder 2\tradex_opinionTrading\codes_2\mybets.py", line 44, in get_event_holdings
    port_dict = self._get_portfolio_dict()
  File "D:\Synced folder 2\tradex_opinionTrading\codes_2\mybets.py", line 41, in _get_portfolio_dict
    return portfolio_dict
UnboundLocalError: local variable 'portfolio_dict' referenced before assignment
ERROR:__main__:2022-12-14 22:18:57,812:local variable 'portfolio_dict' referenced before assignment
Traceback (most recent call last):
  File "D:\Synced folder 2\tradex_opinionTrading\codes_2\main_strategy_run.py", line 128, in <module>
    strat_obj_dict[j].update()
  File "D:\Synced folder 2\tradex_opinionTrading\codes_2\strat7.py", line 614, in update
    self._keep_a_check()
  File "D:\Synced folder 2\tradex_opinionTrading\codes_2\strat7.py", line 568, in _keep_a_check
    self.__scalp_side("Y", trigger, pausebuy=False)
  File "D:\Synced folder 2\tradex_opinionTrading\codes_2\strat7.py", line 255, in __scalp_side
    if (temp_qty > 0) and (temp_price <= self.stop_buy_upper_price) and (not self.order.is_same_order("Y", temp_price, temp_qty, "buy")) and (not self._is_myorder_best("Y")):
  File "D:\Synced folder 2\tradex_opinionTrading\codes_2\order.py", line 143, in is_same_order
    df = self.mybet.get_event_holdings(self.event_id)
  File "D:\Synced folder 2\tradex_opinionTrading\codes_2\mybets.py", line 44, in get_event_holdings
    port_dict = self._get_portfolio_dict()
  File "D:\Synced folder 2\tradex_opinionTrading\codes_2\mybets.py", line 41, in _get_portfolio_dict
    return portfolio_dict
UnboundLocalError: local variable 'portfolio_dict' referenced before assignment
ERROR:__main__:2022-12-14 23:00:25,206:MaxAttempt(3) exhausted. User0
Traceback (most recent call last):
  File "D:\Synced folder 2\tradex_opinionTrading\codes_2\venv\lib\site-packages\requests\models.py", line 971, in json
    return complexjson.loads(self.text, **kwargs)
  File "C:\Users\aniru\AppData\Local\Programs\Python\Python310\lib\json\__init__.py", line 346, in loads
    return _default_decoder.decode(s)
  File "C:\Users\aniru\AppData\Local\Programs\Python\Python310\lib\json\decoder.py", line 337, in decode
    obj, end = self.raw_decode(s, idx=_w(s, 0).end())
  File "C:\Users\aniru\AppData\Local\Programs\Python\Python310\lib\json\decoder.py", line 355, in raw_decode
    raise JSONDecodeError("Expecting value", s, err.value) from None
json.decoder.JSONDecodeError: Expecting value: line 1 column 1 (char 0)

During handling of the above exception, another exception occurred:

Traceback (most recent call last):
  File "D:\Synced folder 2\tradex_opinionTrading\codes_2\api_caller.py", line 118, in tradex_caller
    response = req.post(url, data=body, headers=headers).json()
  File "D:\Synced folder 2\tradex_opinionTrading\codes_2\venv\lib\site-packages\requests\models.py", line 975, in json
    raise RequestsJSONDecodeError(e.msg, e.doc, e.pos)
requests.exceptions.JSONDecodeError: Expecting value: line 1 column 1 (char 0)

During handling of the above exception, another exception occurred:

Traceback (most recent call last):
  File "D:\Synced folder 2\tradex_opinionTrading\codes_2\main_strategy_run.py", line 128, in <module>
    strat_obj_dict[j].update()
  File "D:\Synced folder 2\tradex_opinionTrading\codes_2\strat7.py", line 614, in update
    self._keep_a_check()
  File "D:\Synced folder 2\tradex_opinionTrading\codes_2\strat7.py", line 568, in _keep_a_check
    self.__scalp_side("Y", trigger, pausebuy=False)
  File "D:\Synced folder 2\tradex_opinionTrading\codes_2\strat7.py", line 261, in __scalp_side
    self.order.cancel_all_pending_sell("Y", f"{trigger},NewSellParams")
  File "D:\Synced folder 2\tradex_opinionTrading\codes_2\order.py", line 123, in cancel_all_pending_sell
    self._cancel_sell(message=message,
  File "D:\Synced folder 2\tradex_opinionTrading\codes_2\order.py", line 107, in _cancel_sell
    response = self.api_obj.tradex_caller(suffix, body)
  File "D:\Synced folder 2\tradex_opinionTrading\codes_2\api_caller.py", line 140, in tradex_caller
    raise Exception(f"MaxAttempt({retry_attempts}) exhausted. User{self.userid}")
Exception: MaxAttempt(3) exhausted. User0
ERROR:__main__:2022-12-14 23:01:10,306:MaxAttempt(3) exhausted. User0
Traceback (most recent call last):
  File "D:\Synced folder 2\tradex_opinionTrading\codes_2\venv\lib\site-packages\requests\models.py", line 971, in json
    return complexjson.loads(self.text, **kwargs)
  File "C:\Users\aniru\AppData\Local\Programs\Python\Python310\lib\json\__init__.py", line 346, in loads
    return _default_decoder.decode(s)
  File "C:\Users\aniru\AppData\Local\Programs\Python\Python310\lib\json\decoder.py", line 337, in decode
    obj, end = self.raw_decode(s, idx=_w(s, 0).end())
  File "C:\Users\aniru\AppData\Local\Programs\Python\Python310\lib\json\decoder.py", line 355, in raw_decode
    raise JSONDecodeError("Expecting value", s, err.value) from None
json.decoder.JSONDecodeError: Expecting value: line 1 column 1 (char 0)

During handling of the above exception, another exception occurred:

Traceback (most recent call last):
  File "D:\Synced folder 2\tradex_opinionTrading\codes_2\api_caller.py", line 118, in tradex_caller
    response = req.post(url, data=body, headers=headers).json()
  File "D:\Synced folder 2\tradex_opinionTrading\codes_2\venv\lib\site-packages\requests\models.py", line 975, in json
    raise RequestsJSONDecodeError(e.msg, e.doc, e.pos)
requests.exceptions.JSONDecodeError: Expecting value: line 1 column 1 (char 0)

During handling of the above exception, another exception occurred:

Traceback (most recent call last):
  File "D:\Synced folder 2\tradex_opinionTrading\codes_2\main_strategy_run.py", line 128, in <module>
    strat_obj_dict[j].update()
  File "D:\Synced folder 2\tradex_opinionTrading\codes_2\strat7.py", line 614, in update
    self._keep_a_check()
  File "D:\Synced folder 2\tradex_opinionTrading\codes_2\strat7.py", line 526, in _keep_a_check
    self.__scalp_side("N", trigger, pausebuy=True)
  File "D:\Synced folder 2\tradex_opinionTrading\codes_2\strat7.py", line 287, in __scalp_side
    self.__send_all_sell(f"{trigger},SellingOppSideBoughtQty,{set_priceqty_message}", "Y", sell_price, sell_qty)
  File "D:\Synced folder 2\tradex_opinionTrading\codes_2\strat7.py", line 486, in __send_all_sell
    self.order._sell(message, "Y", sell_price, sell_qty)
  File "D:\Synced folder 2\tradex_opinionTrading\codes_2\order.py", line 63, in _sell
    response = self.api_obj.tradex_caller(suffix, body)
  File "D:\Synced folder 2\tradex_opinionTrading\codes_2\api_caller.py", line 140, in tradex_caller
    raise Exception(f"MaxAttempt({retry_attempts}) exhausted. User{self.userid}")
Exception: MaxAttempt(3) exhausted. User0
ERROR:__main__:2022-12-14 23:01:52,872:MaxAttempt(3) exhausted. User0
Traceback (most recent call last):
  File "D:\Synced folder 2\tradex_opinionTrading\codes_2\venv\lib\site-packages\requests\models.py", line 971, in json
    return complexjson.loads(self.text, **kwargs)
  File "C:\Users\aniru\AppData\Local\Programs\Python\Python310\lib\json\__init__.py", line 346, in loads
    return _default_decoder.decode(s)
  File "C:\Users\aniru\AppData\Local\Programs\Python\Python310\lib\json\decoder.py", line 337, in decode
    obj, end = self.raw_decode(s, idx=_w(s, 0).end())
  File "C:\Users\aniru\AppData\Local\Programs\Python\Python310\lib\json\decoder.py", line 355, in raw_decode
    raise JSONDecodeError("Expecting value", s, err.value) from None
json.decoder.JSONDecodeError: Expecting value: line 1 column 1 (char 0)

During handling of the above exception, another exception occurred:

Traceback (most recent call last):
  File "D:\Synced folder 2\tradex_opinionTrading\codes_2\api_caller.py", line 118, in tradex_caller
    response = req.post(url, data=body, headers=headers).json()
  File "D:\Synced folder 2\tradex_opinionTrading\codes_2\venv\lib\site-packages\requests\models.py", line 975, in json
    raise RequestsJSONDecodeError(e.msg, e.doc, e.pos)
requests.exceptions.JSONDecodeError: Expecting value: line 1 column 1 (char 0)

During handling of the above exception, another exception occurred:

Traceback (most recent call last):
  File "D:\Synced folder 2\tradex_opinionTrading\codes_2\main_strategy_run.py", line 128, in <module>
    strat_obj_dict[j].update()
  File "D:\Synced folder 2\tradex_opinionTrading\codes_2\strat7.py", line 614, in update
    self._keep_a_check()
  File "D:\Synced folder 2\tradex_opinionTrading\codes_2\strat7.py", line 524, in _keep_a_check
    self.__scalp_side("N", trigger, pausebuy=False)
  File "D:\Synced folder 2\tradex_opinionTrading\codes_2\strat7.py", line 275, in __scalp_side
    self.__send_buy_orders(f"{trigger},ScalpingNo,{set_priceqty_message}", "N", temp_price, temp_qty)
  File "D:\Synced folder 2\tradex_opinionTrading\codes_2\strat7.py", line 482, in __send_buy_orders
    self.order._buy(message, "N", price, qty)
  File "D:\Synced folder 2\tradex_opinionTrading\codes_2\order.py", line 38, in _buy
    response = self.api_obj.tradex_caller(suffix, body)
  File "D:\Synced folder 2\tradex_opinionTrading\codes_2\api_caller.py", line 140, in tradex_caller
    raise Exception(f"MaxAttempt({retry_attempts}) exhausted. User{self.userid}")
Exception: MaxAttempt(3) exhausted. User0
