ERROR:__main__:2022-12-15 14:54:53,704:'title'
Traceback (most recent call last):
  File "D:\Synced folder 2\tradex_opinionTrading\codes_2\main_strategy_run.py", line 115, in <module>
    strat_obj_dict[i].initialise()
  File "D:\Synced folder 2\tradex_opinionTrading\codes_2\strat7.py", line 580, in initialise
    self.priceatri.initialise_priceatri()
  File "D:\Synced folder 2\tradex_opinionTrading\codes_2\price_attributes.py", line 90, in initialise_priceatri
    self.initialise_event()
  File "D:\Synced folder 2\tradex_opinionTrading\codes_2\event_params.py", line 22, in initialise_event
    self.title = static_data["title"]
KeyError: 'title'
ERROR:__main__:2022-12-15 14:54:53,781:fromisoformat: argument must be str
Traceback (most recent call last):
  File "D:\Synced folder 2\tradex_opinionTrading\codes_2\main_strategy_run.py", line 124, in <module>
    while dt.datetime.now() <= dt.datetime.fromisoformat(strat_obj_dict[i].priceatri.ends_at):
TypeError: fromisoformat: argument must be str
ERROR:__main__:2022-12-15 15:31:37,677:('Connection aborted.', RemoteDisconnected('Remote end closed connection without response'))
Traceback (most recent call last):
  File "D:\Synced folder 2\tradex_opinionTrading\codes_2\venv\lib\site-packages\urllib3\connectionpool.py", line 703, in urlopen
    httplib_response = self._make_request(
  File "D:\Synced folder 2\tradex_opinionTrading\codes_2\venv\lib\site-packages\urllib3\connectionpool.py", line 449, in _make_request
    six.raise_from(e, None)
  File "<string>", line 3, in raise_from
  File "D:\Synced folder 2\tradex_opinionTrading\codes_2\venv\lib\site-packages\urllib3\connectionpool.py", line 444, in _make_request
    httplib_response = conn.getresponse()
  File "C:\Users\aniru\AppData\Local\Programs\Python\Python310\lib\http\client.py", line 1374, in getresponse
    response.begin()
  File "C:\Users\aniru\AppData\Local\Programs\Python\Python310\lib\http\client.py", line 318, in begin
    version, status, reason = self._read_status()
  File "C:\Users\aniru\AppData\Local\Programs\Python\Python310\lib\http\client.py", line 287, in _read_status
    raise RemoteDisconnected("Remote end closed connection without"
http.client.RemoteDisconnected: Remote end closed connection without response

During handling of the above exception, another exception occurred:

Traceback (most recent call last):
  File "D:\Synced folder 2\tradex_opinionTrading\codes_2\venv\lib\site-packages\requests\adapters.py", line 489, in send
    resp = conn.urlopen(
  File "D:\Synced folder 2\tradex_opinionTrading\codes_2\venv\lib\site-packages\urllib3\connectionpool.py", line 787, in urlopen
    retries = retries.increment(
  File "D:\Synced folder 2\tradex_opinionTrading\codes_2\venv\lib\site-packages\urllib3\util\retry.py", line 550, in increment
    raise six.reraise(type(error), error, _stacktrace)
  File "D:\Synced folder 2\tradex_opinionTrading\codes_2\venv\lib\site-packages\urllib3\packages\six.py", line 769, in reraise
    raise value.with_traceback(tb)
  File "D:\Synced folder 2\tradex_opinionTrading\codes_2\venv\lib\site-packages\urllib3\connectionpool.py", line 703, in urlopen
    httplib_response = self._make_request(
  File "D:\Synced folder 2\tradex_opinionTrading\codes_2\venv\lib\site-packages\urllib3\connectionpool.py", line 449, in _make_request
    six.raise_from(e, None)
  File "<string>", line 3, in raise_from
  File "D:\Synced folder 2\tradex_opinionTrading\codes_2\venv\lib\site-packages\urllib3\connectionpool.py", line 444, in _make_request
    httplib_response = conn.getresponse()
  File "C:\Users\aniru\AppData\Local\Programs\Python\Python310\lib\http\client.py", line 1374, in getresponse
    response.begin()
  File "C:\Users\aniru\AppData\Local\Programs\Python\Python310\lib\http\client.py", line 318, in begin
    version, status, reason = self._read_status()
  File "C:\Users\aniru\AppData\Local\Programs\Python\Python310\lib\http\client.py", line 287, in _read_status
    raise RemoteDisconnected("Remote end closed connection without"
urllib3.exceptions.ProtocolError: ('Connection aborted.', RemoteDisconnected('Remote end closed connection without response'))

During handling of the above exception, another exception occurred:

Traceback (most recent call last):
  File "D:\Synced folder 2\tradex_opinionTrading\codes_2\main_strategy_run.py", line 115, in <module>
    strat_obj_dict[i].initialise()
  File "D:\Synced folder 2\tradex_opinionTrading\codes_2\strat7.py", line 584, in initialise
    self.__set_atr_value()
  File "D:\Synced folder 2\tradex_opinionTrading\codes_2\strat7.py", line 110, in __set_atr_value
    self.atr_value = self.binance_obj.get_last_atr(symbol="BTCUSDT", interval=self.time_2_expiry_cat)
  File "D:\Synced folder 2\tradex_opinionTrading\codes_2\binance_data.py", line 57, in get_last_atr
    data = self.fetch_hist_data(symbol, interval)
  File "D:\Synced folder 2\tradex_opinionTrading\codes_2\binance_data.py", line 28, in fetch_hist_data
    data = self.client.get_historical_klines(symbol, interval_dict[interval], "1 day ago UTC")
  File "D:\Synced folder 2\tradex_opinionTrading\codes_2\venv\lib\site-packages\binance\client.py", line 934, in get_historical_klines
    return self._historical_klines(
  File "D:\Synced folder 2\tradex_opinionTrading\codes_2\venv\lib\site-packages\binance\client.py", line 973, in _historical_klines
    first_valid_ts = self._get_earliest_valid_timestamp(symbol, interval, klines_type)
  File "D:\Synced folder 2\tradex_opinionTrading\codes_2\venv\lib\site-packages\binance\client.py", line 904, in _get_earliest_valid_timestamp
    kline = self._klines(
  File "D:\Synced folder 2\tradex_opinionTrading\codes_2\venv\lib\site-packages\binance\client.py", line 883, in _klines
    return self.get_klines(**params)
  File "D:\Synced folder 2\tradex_opinionTrading\codes_2\venv\lib\site-packages\binance\client.py", line 868, in get_klines
    return self._get('klines', data=params, version=self.PRIVATE_API_VERSION)
  File "D:\Synced folder 2\tradex_opinionTrading\codes_2\venv\lib\site-packages\binance\client.py", line 371, in _get
    return self._request_api('get', path, signed, version, **kwargs)
  File "D:\Synced folder 2\tradex_opinionTrading\codes_2\venv\lib\site-packages\binance\client.py", line 334, in _request_api
    return self._request(method, uri, signed, **kwargs)
  File "D:\Synced folder 2\tradex_opinionTrading\codes_2\venv\lib\site-packages\binance\client.py", line 314, in _request
    self.response = getattr(self.session, method)(uri, **kwargs)
  File "D:\Synced folder 2\tradex_opinionTrading\codes_2\venv\lib\site-packages\requests\sessions.py", line 600, in get
    return self.request("GET", url, **kwargs)
  File "D:\Synced folder 2\tradex_opinionTrading\codes_2\venv\lib\site-packages\requests\sessions.py", line 587, in request
    resp = self.send(prep, **send_kwargs)
  File "D:\Synced folder 2\tradex_opinionTrading\codes_2\venv\lib\site-packages\requests\sessions.py", line 701, in send
    r = adapter.send(request, **kwargs)
  File "D:\Synced folder 2\tradex_opinionTrading\codes_2\venv\lib\site-packages\requests\adapters.py", line 547, in send
    raise ConnectionError(err, request=request)
requests.exceptions.ConnectionError: ('Connection aborted.', RemoteDisconnected('Remote end closed connection without response'))
ERROR:__main__:2022-12-15 18:40:01,577:local variable 'portfolio_dict' referenced before assignment
Traceback (most recent call last):
  File "D:\Synced folder 2\tradex_opinionTrading\codes_2\main_strategy_run.py", line 128, in <module>
    strat_obj_dict[j].update()
  File "D:\Synced folder 2\tradex_opinionTrading\codes_2\strat7.py", line 614, in update
    self._keep_a_check()
  File "D:\Synced folder 2\tradex_opinionTrading\codes_2\strat7.py", line 575, in _keep_a_check
    self.__scalp_side("N", trigger, pausebuy=True)
  File "D:\Synced folder 2\tradex_opinionTrading\codes_2\strat7.py", line 279, in __scalp_side
    self.order.cancel_all_pending_sell("N", f"{trigger},NewSellParams")
  File "D:\Synced folder 2\tradex_opinionTrading\codes_2\order.py", line 142, in cancel_all_pending_sell
    df = self.mybet.get_event_holdings(self.event_id)
  File "D:\Synced folder 2\tradex_opinionTrading\codes_2\mybets.py", line 44, in get_event_holdings
    port_dict = self._get_portfolio_dict()
  File "D:\Synced folder 2\tradex_opinionTrading\codes_2\mybets.py", line 41, in _get_portfolio_dict
    return portfolio_dict
UnboundLocalError: local variable 'portfolio_dict' referenced before assignment
ERROR:__main__:2022-12-15 21:19:14,569:local variable 'portfolio_dict' referenced before assignment
Traceback (most recent call last):
  File "D:\Synced folder 2\tradex_opinionTrading\codes_2\main_strategy_run.py", line 128, in <module>
    strat_obj_dict[j].update()
  File "D:\Synced folder 2\tradex_opinionTrading\codes_2\strat7.py", line 614, in update
    self._keep_a_check()
  File "D:\Synced folder 2\tradex_opinionTrading\codes_2\strat7.py", line 524, in _keep_a_check
    self.__scalp_side("N", trigger, pausebuy=False)
  File "D:\Synced folder 2\tradex_opinionTrading\codes_2\strat7.py", line 273, in __scalp_side
    if (temp_qty > 0) and (temp_price <= self.stop_buy_upper_price) and (not self.order.is_same_order("N", temp_price, temp_qty, "buy")) and (not self._is_myorder_best("N")):
  File "D:\Synced folder 2\tradex_opinionTrading\codes_2\order.py", line 170, in is_same_order
    df = self.mybet.get_event_holdings(self.event_id)
  File "D:\Synced folder 2\tradex_opinionTrading\codes_2\mybets.py", line 44, in get_event_holdings
    port_dict = self._get_portfolio_dict()
  File "D:\Synced folder 2\tradex_opinionTrading\codes_2\mybets.py", line 41, in _get_portfolio_dict
    return portfolio_dict
UnboundLocalError: local variable 'portfolio_dict' referenced before assignment
ERROR:__main__:2022-12-15 23:01:11,694:MaxAttempt(3) exhausted. User0
Traceback (most recent call last):
  File "D:\Synced folder 2\tradex_opinionTrading\codes_2\venv\lib\site-packages\requests\models.py", line 971, in json
    return complexjson.loads(self.text, **kwargs)
  File "C:\Users\aniru\AppData\Local\Programs\Python\Python310\lib\json\__init__.py", line 346, in loads
    return _default_decoder.decode(s)
  File "C:\Users\aniru\AppData\Local\Programs\Python\Python310\lib\json\decoder.py", line 337, in decode
    obj, end = self.raw_decode(s, idx=_w(s, 0).end())
  File "C:\Users\aniru\AppData\Local\Programs\Python\Python310\lib\json\decoder.py", line 355, in raw_decode
    raise JSONDecodeError("Expecting value", s, err.value) from None
json.decoder.JSONDecodeError: Expecting value: line 1 column 1 (char 0)

During handling of the above exception, another exception occurred:

Traceback (most recent call last):
  File "D:\Synced folder 2\tradex_opinionTrading\codes_2\api_caller.py", line 118, in tradex_caller
    response = req.post(url, data=body, headers=headers).json()
  File "D:\Synced folder 2\tradex_opinionTrading\codes_2\venv\lib\site-packages\requests\models.py", line 975, in json
    raise RequestsJSONDecodeError(e.msg, e.doc, e.pos)
requests.exceptions.JSONDecodeError: Expecting value: line 1 column 1 (char 0)

During handling of the above exception, another exception occurred:

Traceback (most recent call last):
  File "D:\Synced folder 2\tradex_opinionTrading\codes_2\main_strategy_run.py", line 128, in <module>
    strat_obj_dict[j].update()
  File "D:\Synced folder 2\tradex_opinionTrading\codes_2\strat7.py", line 614, in update
    self._keep_a_check()
  File "D:\Synced folder 2\tradex_opinionTrading\codes_2\strat7.py", line 524, in _keep_a_check
    self.__scalp_side("N", trigger, pausebuy=False)
  File "D:\Synced folder 2\tradex_opinionTrading\codes_2\strat7.py", line 275, in __scalp_side
    self.__send_buy_orders(f"{trigger},ScalpingNo,{set_priceqty_message}", "N", temp_price, temp_qty)
  File "D:\Synced folder 2\tradex_opinionTrading\codes_2\strat7.py", line 482, in __send_buy_orders
    self.order._buy(message, "N", price, qty)
  File "D:\Synced folder 2\tradex_opinionTrading\codes_2\order.py", line 38, in _buy
    response = self.api_obj.tradex_caller(suffix, body)
  File "D:\Synced folder 2\tradex_opinionTrading\codes_2\api_caller.py", line 140, in tradex_caller
    raise Exception(f"MaxAttempt({retry_attempts}) exhausted. User{self.userid}")
Exception: MaxAttempt(3) exhausted. User0
